Workbook

Sheet Utsendte tilbud
A1: Utsendte tilbud | D1: =TODAY() -> 46001
AC2: SALG
P3: Tapt | Q3: =COUNTIFS(P9:P454,"Tapt") -> 56 | T3: Ordre | U3: =COUNTIFS(P9:P454,"Ordre") -> 31 | AG3: Oms | AH3: =#REF!-#REF! -> #REF! | AI3: =#REF!-#REF! -> #REF!
P4: Tilbud | Q4: =SUMIF(P9:P454,"Tilbud",G9:G454) -> 732162 | R4: m² | T4: Ferdig | U4: =COUNTIFS(P9:P454,"Ferdig") -> 61 | AC4: Oms | AD4: 118245404 | AE4: 60273913 | AG4: m² | AH4: =#REF!-#REF! -> #REF! | AI4: =#REF!-#REF! -> #REF!
P5: Tilbud | Q5: =SUMIF(P9:P454,"Tilbud",Q9:Q454) -> 573254809 | R5: kr | T5: Ordre | U5: =SUMIF(P9:P454,"Ordre",G9:G454) -> 86505 | V5: m² | AC5: m² | AD5: 182925 | AE5: 93312 | AG5: Antall tilbud avgjort | AH5: =#REF!-#REF! -> #REF! | AI5: =#REF!-#REF! -> #REF!
P6: Tilbud | Q6: =COUNTIFS(P9:P454,"Tilbud") -> 259 | R6: antall | T6: Ferdig | U6: =SUMIF(P9:P454,"Ferdig",G9:G454) -> 284555 | V6: m² | X6: m² | Y6: =SUMIF(Y9:Y419,"x",G9:G387) -> 358635 | Z6: =SUMIF(Z9:Z419,"x",G9:G387) -> 284303 | AA6: =SUMIF(AA9:AA419,"x",G9:G387) -> 271599 | AC6: Antall tilbud avgjort | AD6: 34 | AE6: 16 | AG6: Kalk DB | AH6: =#REF!-#REF! -> #REF!
AC7: Antall | AD7: 0.29824561 | AE7: 0.14035088 | AG7: Verdi
A8: Sendt | B8: Ansvarlig | C8: Kunde / Byggherre | D8: Prosjekt | E8: Frist | F8: Beliggenhet | G8: m² | H8: Timer | I8: Forventet oppstart | J8: Sedum | K8: Tilbudt sum Sedum | L8: Tilbud til oss Sedum | M8: DB Sedum | N8: pris m² | O8: DG Sedum | P8: Status | Q8: Tilbudspris | R8: DG | S8: DB | T8: Pris m² | U8: Vedståelses frist | V8: Sist oppdatert | W8: Beskrivelse / siste nytt | X8: Prioritet | Y8: Solgt | Z8: Ferdig | AA8: Tapt | AC8: Verdi | AD8: 0.30149979 | AE8: 0.15368523
A9: 45077 | B9: HSK | C9: Gressvik Properties | D9: 22000 Hjalmar Bjørges vei 105 | F9: Fredrikstad | G9: 3200 | H9: 792 | I9: Høst' 23 | P9: BUDSJETT | Q9: 2303570 | R9: 0.35 | S9: =Q9*R9 -> 806249.5 | T9: =Q9/G9 -> 719.86563 | U9: =IF(A9="","",(A9+60)) -> 45137 | Y9: =IF(OR(P9="Ordre",P9="Ferdig"),"x","") | Z9: =IF(P9="Ferdig","x","") | AA9: =IF(P9="Tapt","x","")
A10: 44876 | B10: HSK | C10: Hallgruppen AS | D10: 22001 Apilar | F10: Røyken/ Hurum | G10: 1621 | I10: Februar | K10: =IF(L10="","",(ROUNDUP(L10+M10,-1))) | P10: Ferdig | Q10: 1215000 | R10: 0.16 | S10: =Q10*R10 -> 194400 | T10: =Q10/G10 -> 749.53732 | U10: =IF(A10="","",(A10+60)) -> 44936 | V10: 44845 | W10: Seksjonert PIR er ok RIBr. Priset inn. | Y10: =IF(OR(P10="Ordre",P10="Ferdig"),"x","") -> x | Z10: =IF(P10="Ferdig","x","") -> x | AA10: =IF(P10="Tapt","x","")
A11: 44876 | B11: HSK | C11: Hallgruppen AS | D11: 22002 Killingmo Freseservicve | F11: Gardermoen | G11: 1553 | I11: Februar | K11: =IF(L11="","",(ROUNDUP(L11+M11,-1))) | P11: Ferdig | Q11: 1185100 | R11: 0.2204 | S11: =Q11*R11 -> 261196.04 | T11: =Q11/G11 -> 763.10367 | U11: =IF(A11="","",(A11+60)) -> 44936 | V11: 44845 | W11: Stål sier PIR fullt ut på lagerdelen. Kun mineralull på kontordelen. | Y11: =IF(OR(P11="Ordre",P11="Ferdig"),"x","") -> x | Z11: =IF(P11="Ferdig","x","") -> x | AA11: =IF(P11="Tapt","x","")
A12: 44876 | B12: HSK | C12: Hallgruppen AS | D12: 22003 Aurevegen 2 | F12: Gardermoen | G12: 2400 | I12: Februar | K12: =IF(L12="","",(ROUNDUP(L12+M12,-1))) | P12: Ferdig | Q12: 1738750 | R12: 0.2348 | S12: =Q12*R12 -> 408258.5 | T12: =Q12/G12 -> 724.47917 | U12: =IF(A12="","",(A12+60)) -> 44936 | V12: 44845 | W12: Stål sier PIR full ut. Priset inn. | Y12: =IF(OR(P12="Ordre",P12="Ferdig"),"x","") -> x | Z12: =IF(P12="Ferdig","x","") -> x | AA12: =IF(P12="Tapt","x","")
A13: 45604 | B13: HSK | C13: Straye Stålbygg AS | D13: 22004 Coop Geithus | F13: Geithus | G13: 1228 | K13: =IF(L13="","",(ROUNDUP(L13+M13,-1))) | P13: Tapt | Q13: 1095000 | R13: 0.164 | S13: =Q13*R13 -> 179580 | T13: =Q13/G13 -> 891.69381 | U13: =IF(A13="","",(A13+60)) -> 45664 | V13: 44966 | W13: Valgt annen leverandør | Y13: =IF(OR(P13="Ordre",P13="Ferdig"),"x","") | Z13: =IF(P13="Ferdig","x","") | AA13: =IF(P13="Tapt","x","") -> x
A14: 44881 | B14: HSK | C14: KM Bygg | D14: 22005 Byggmax Geithus | F14: Geithus | G14: 1514 | K14: =IF(L14="","",(ROUNDUP(L14+M14,-1))) | P14: Tapt | Q14: 1347290 | R14: 0.161 | S14: =Q14*R14 -> 216913.69 | T14: =Q14/G14 -> 889.88771 | U14: =IF(A14="","",(A14+60)) -> 44941 | V14: 44966 | W14: Valgt annen leverandør | Y14: =IF(OR(P14="Ordre",P14="Ferdig"),"x","") | Z14: =IF(P14="Ferdig","x","") | AA14: =IF(P14="Tapt","x","") -> x
A15: 44882 | B15: HSK | C15: Straye Stålbygg | D15: 22006 Ihlen Lager Askim | F15: Askim | G15: 5400 | I15: Uke 9?? | K15: =IF(L15="","",(ROUNDUP(L15+M15,-1))) | P15: Ferdig | Q15: 3420000 | R15: 0.1604 | S15: =Q15*R15 -> 548568 | T15: =Q15/G15 -> 633.33333 | U15: =IF(A15="","",(A15+60)) -> 44942 | W15: Forsøker få gjennom PIR også her. Uke 10 på tekking | Y15: =IF(OR(P15="Ordre",P15="Ferdig"),"x","") -> x | Z15: =IF(P15="Ferdig","x","") -> x | AA15: =IF(P15="Tapt","x","")
A16: 44889 | B16: HSK | C16: Hallgruppen AS | D16: 22007 Brobekkveien 84 | F16: Oslo | G16: 870 | K16: =IF(L16="","",(ROUNDUP(L16+M16,-1))) | P16: Tapt | Q16: =1089000-35000 -> 1054000 | R16: 0.172 | S16: =Q16*R16 -> 181288 | T16: =Q16/G16 -> 1211.4943 | U16: =IF(A16="","",(A16+60)) -> 44949 | V16: 44995 | W16: Stålbygg har muntlig avtale. Avklare utførelse… Trond L | Y16: =IF(OR(P16="Ordre",P16="Ferdig"),"x","") | Z16: =IF(P16="Ferdig","x","") | AA16: =IF(P16="Tapt","x","") -> x
A17: 44971 | B17: HSK | C17: Seby AS/ Veidekke AS | D17: 22008 OneMed | F17: Gardermoen | G17: 17685 | I17: Høst '22 | K17: =IF(L17="","",(ROUNDUP(L17+M17,-1))) | P17: Tapt | Q17: 11067940 | R17: 0.1608 | S17: =Q17*R17 -> 1779724.8 | T17: =Q17/G17 -> 625.83772 | U17: =IF(A17="","",(A17+60)) -> 45031 | V17: 44973 | W17: Alternativ pris gitt med 0,13. Jobber med RIBr | X17: 1 | Y17: =IF(OR(P17="Ordre",P17="Ferdig"),"x","") | Z17: =IF(P17="Ferdig","x","") | AA17: =IF(P17="Tapt","x","") -> x
A18: 45196 | B18: HSK | C18: Straye Stålbygg AS | D18: 22010 Sofiemyr Tennishall | F18: Sofiemyr | G18: 2900 | I18: juni | P18: Ferdig | Q18: 2300000 | R18: 0.17 | S18: =Q18*R18 -> 391000 | T18: =Q18/G18 -> 793.10345 | U18: =IF(A18="","",(A18+60)) -> 45256 | W18: Denne SKAL vi ha!! | Y18: =IF(OR(P18="Ordre",P18="Ferdig"),"x","") -> x | Z18: =IF(P18="Ferdig","x","") -> x | AA18: =IF(P18="Tapt","x","")
A19: 44893 | B19: HSK | C19: Park & Anlegg | D19: 22011 Schenker Østfold | F19: Moss | G19: 6983 | I19: Q3- 23 | J19: X | K19: =IF(L19="","",(ROUNDUP(L19+M19,-1))) -> 1855130 | L19: 1686475 | M19: =L19*O19 -> 168647.5 | N19: =L19/3500 -> 481.85 | O19: 0.1 | P19: UTGÅR | Q19: 4399000 | R19: 0.2078 | S19: =Q19*R19 -> 914112.2 | T19: =Q19/G19 -> 629.95847 | U19: =IF(A19="","",(A19+60)) -> 44953 | V19: 45385 | W19: Henrik følger opp!! Fredrik har fulgt opp stål- avventer svar. Satt på vent??? | Y19: =IF(OR(P19="Ordre",P19="Ferdig"),"x","") | Z19: =IF(P19="Ferdig","x","") | AA19: =IF(P19="Tapt","x","")
A20: 44894 | B20: HSK | C20: Straye Stålbygg AS | D20: 22012 Lagerhall Jowa | F20: Sarpsborg | G20: 2400 | P20: Tapt | Q20: 1585600 | R20: 0.1972 | S20: =Q20*R20 -> 312680.32 | T20: =Q20/G20 -> 660.66667 | U20: =IF(A20="","",(A20+60)) -> 44954 | V20: 45385 | W20: Uvist- Vår -24??? | Y20: =IF(OR(P20="Ordre",P20="Ferdig"),"x","") | Z20: =IF(P20="Ferdig","x","") | AA20: =IF(P20="Tapt","x","") -> x
A21: 44895 | B21: HSK | C21: Thermica AS | D21: 22013 NREP Moss | F21: Moss | G21: 30604 | I21: Q3- 23 | P21: BUDSJETT | Q21: 16445000 | R21: 0.1764 | S21: =Q21*R21 -> 2900898 | T21: =Q21/G21 -> 537.34806 | U21: =IF(A21="","",(A21+60)) -> 44955 | V21: 45385 | W21: BUDSJETT Se Vestre Vanemvei | X21: 5 | Y21: =IF(OR(P21="Ordre",P21="Ferdig"),"x","") | Z21: =IF(P21="Ferdig","x","") | AA21: =IF(P21="Tapt","x","")
A22: 44966 | B22: HSK | C22: Straye Stålbygg AS | D22: 22014 Ordfører Utnes vei 51 | F22: Rygge | G22: 1187 | I22: JUNI-JULI | P22: Ferdig | Q22: 828000 | R22: 0.1882 | S22: =Q22*R22 -> 155829.6 | T22: =Q22/G22 -> 697.55687 | U22: =IF(A22="","",(A22+60)) -> 45026 | V22: 44995 | W22: SB møte med Holmskau uke 11 | Y22: =IF(OR(P22="Ordre",P22="Ferdig"),"x","") -> x | Z22: =IF(P22="Ferdig","x","") -> x | AA22: =IF(P22="Tapt","x","")
A23: 44862 | B23: HSK | C23: Straye Stålbygg | D23: 22015 Coop ørebekk | F23: Fredrikstad | G23: =4800+3424 -> 8224 | I23: Sommer '23 | K23: =IF(L23="","",(ROUNDUP(L23+M23,-1))) | P23: Ferdig | Q23: 6204000 | R23: 0.17 | S23: =Q23*R23 -> 1054680 | T23: =Q23/G23 -> 754.37743 | U23: =IF(A23="","",(A23+60)) -> 44922 | V23: 44973 | W23: Fått jobben SB. Stålbygg er kunde! | Y23: =IF(OR(P23="Ordre",P23="Ferdig"),"x","") -> x | Z23: =IF(P23="Ferdig","x","") -> x | AA23: =IF(P23="Tapt","x","")
A24: 44901 | B24: HSK | C24: Straye Stålbygg AS | D24: 22019 Skjeberg Marinesenter | F24: Skjeberg | G24: 1715 | P24: Ferdig | Q24: 1087440 | R24: 0.172 | S24: =Q24*R24 -> 187039.68 | T24: =Q24/G24 -> 634.0758 | U24: =IF(A24="","",(A24+60)) -> 44961 | Y24: =IF(OR(P24="Ordre",P24="Ferdig"),"x","") -> x | Z24: =IF(P24="Ferdig","x","") -> x | AA24: =IF(P24="Tapt","x","")
A25: 44910 | B25: HSK | C25: Nordbygg AS | D25: 22022 Kongeveien 49 | F25: Sofiemyr | G25: 5259 | J25: X | K25: =IF(L25="","",(ROUNDUP(L25+M25,-1))) -> 2423070 | L25: 2202790 | M25: =L25*O25 -> 220279 | N25: =L25/G25 -> 418.861 | O25: 0.1 | P25: Tapt | Q25: 3270880 | R25: 0.194 | S25: =Q25*R25 -> 634550.72 | T25: =Q25/G25 -> 621.95855 | U25: =IF(A25="","",(A25+60)) -> 44970 | V25: 44995 | W25: To bygg samlet. A og C. Tillegg for MU. Jan Erik Henrik | X25: 1 | Y25: =IF(OR(P25="Ordre",P25="Ferdig"),"x","") | Z25: =IF(P25="Ferdig","x","") | AA25: =IF(P25="Tapt","x","") -> x
A26: 44915 | B26: HSK | C26: Straye Stålbygg AS | D26: 22023 Lammenes Næringspark Hvaler | F26: Hvaler | G26: 4949 | P26: BUDSJETT | Q26: 3650875 | R26: 0.195 | S26: =Q26*R26 -> 711920.62 | T26: =Q26/G26 -> 737.69954 | U26: =IF(A26="","",(A26+60)) -> 44975 | V26: 45385 | W26: Holmskau | X26: 2 | Y26: =IF(OR(P26="Ordre",P26="Ferdig"),"x","") | Z26: =IF(P26="Ferdig","x","") | AA26: =IF(P26="Tapt","x","")
A27: 44922 | B27: HSK | C27: Hallgruppen AS | D27: 22025 Dekkhotell Røyken | F27: Røyken/ Hurum | G27: 3808 | I27: mai-juni/ 23 | P27: Ferdig | Q27: 2500000 | R27: 0.2437 | S27: =Q27*R27 -> 609250 | T27: =Q27/G27 -> 656.51261 | U27: =IF(A27="","",(A27+60)) -> 44982 | W27: 2 500 000 avtalt med Daniel. Inkl. trappetårn. | Y27: =IF(OR(P27="Ordre",P27="Ferdig"),"x","") -> x | Z27: =IF(P27="Ferdig","x","") -> x | AA27: =IF(P27="Tapt","x","")
A28: 44986 | B28: HSK | C28: Straye Trebygg AS | D28: 22027 Kiwi Sorgenfri | F28: Fredrikstad | G28: 1514 | P28: Tapt | Q28: 1177580 | R28: 0.22 | S28: =Q28*R28 -> 259067.6 | T28: =Q28/G28 -> 777.79392 | U28: =IF(A28="","",(A28+60)) -> 45046 | Y28: =IF(OR(P28="Ordre",P28="Ferdig"),"x","") | Z28: =IF(P28="Ferdig","x","") | AA28: =IF(P28="Tapt","x","") -> x
A29: 45191 | B29: HSK | C29: Straye Stålbygg AS | D29: 22102 Studio City Norway | F29: Mysen | G29: 7116 | H29: 2268 | P29: UTGÅR | Q29: 5131941 | R29: 0.17 | S29: =Q29*R29 -> 872429.97 | T29: =Q29/G29 -> 721.18339 | U29: =IF(A29="","",(A29+60)) -> 45251 | V29: 45385 | W29: Lunken | Y29: =IF(OR(P29="Ordre",P29="Ferdig"),"x","") | Z29: =IF(P29="Ferdig","x","") | AA29: =IF(P29="Tapt","x","")
A30: 44927 | B30: HSK | C30: Straye Stålbygg AS | D30: 23002 Asko Oslofjord- Kjøreporter | F30: Sande | G30: 125 | I30: jan '23 | P30: Ferdig | Q30: 218320 | R30: 0.393 | S30: =Q30*R30 -> 85799.76 | T30: =Q30/G30 -> 1746.56 | U30: =IF(A30="","",(A30+60)) -> 44987 | Y30: =IF(OR(P30="Ordre",P30="Ferdig"),"x","") -> x | Z30: =IF(P30="Ferdig","x","") -> x | AA30: =IF(P30="Tapt","x","")
A31: 44935 | B31: HSK | C31: Straye Stålbygg AS | D31: 23004 Maxbo Sarpsborg | F31: Sarpsborg | G31: 2367 | P31: Tapt | Q31: 1675000 | R31: 0.2008 | S31: =Q31*R31 -> 336340 | T31: =Q31/G31 -> 707.64681 | U31: =IF(A31="","",(A31+60)) -> 44995 | V31: 45385 | W31: Revideres 10.02.23. Sendes av SB. Sjekk med siste underlag fra Jan Erik. | Y31: =IF(OR(P31="Ordre",P31="Ferdig"),"x","") | Z31: =IF(P31="Ferdig","x","") | AA31: =IF(P31="Tapt","x","") -> x
A32: 45169 | B32: HSK | C32: Peab/ Straye Stålbygg | D32: 23005 Posten Moss | F32: Moss | G32: 20539 | H32: 4532 | P32: Ferdig | Q32: 11886606 | R32: 0.0901 | S32: =Q32*R32 -> 1070983.2 | T32: =Q32/G32 -> 578.73343 | U32: =IF(A32="","",(A32+60)) -> 45229 | W32: Utsatt til 2024/ ubestemt tid- Kalkulert, men ikke sendt til SB. 12,2M Mestertak | Y32: =IF(OR(P32="Ordre",P32="Ferdig"),"x","") -> x | Z32: =IF(P32="Ferdig","x","") -> x | AA32: =IF(P32="Tapt","x","")
A33: 44953 | B33: HSK | C33: Straye Stålbygg AS | D33: 23007 Mekonomen Gjøvik | F33: Gjøvik | P33: Tapt | R33: 0.1383 | S33: =Q33*R33 -> 0 | T33: =Q33/G33 -> #DIV/0! | U33: =IF(A33="","",(A33+60)) -> 45013 | V33: 45385 | W33: UTGÅR- Blitt til Mekonomen Vestby | X33: 2 | Y33: =IF(OR(P33="Ordre",P33="Ferdig"),"x","") | Z33: =IF(P33="Ferdig","x","") | AA33: =IF(P33="Tapt","x","") -> x
A34: 44952 | B34: HSK | C34: Straye Stålbygg AS | D34: 23009 Nett tjenester | G34: 289 | K34: =IF(L34="","",(ROUNDUP(L34+M34,-1))) | M34: =L34*O34 -> 0 | N34: =L34/3500 -> 0 | P34: UTGÅR | Q34: 285000 | R34: 0.171 | S34: =Q34*R34 -> 48735 | T34: =Q34/G34 -> 986.15917 | U34: =IF(A34="","",(A34+60)) -> 45012 | V34: 45385 | W34: Holmskau- På hold?? | Y34: =IF(OR(P34="Ordre",P34="Ferdig"),"x","") | Z34: =IF(P34="Ferdig","x","") | AA34: =IF(P34="Tapt","x","")
A35: 44959 | B35: HSK | C35: A Bygg | D35: 23012 OLD HN1 | F35: Drøbak | G35: 20448 | I35: April-mai | P35: Tapt | Q35: 12254685 | R35: 0.12 | S35: =Q35*R35 -> 1470562.2 | T35: =Q35/G35 -> 599.30971 | U35: =IF(A35="","",(A35+60)) -> 45019 | V35: 44973 | W35: Forsøkt ringe 16.02.2023 | X35: 1 | Y35: =IF(OR(P35="Ordre",P35="Ferdig"),"x","") | Z35: =IF(P35="Ferdig","x","") | AA35: =IF(P35="Tapt","x","") -> x
A36: 45231 | B36: HSK | C36: Straye Stålbygg AS | D36: 23014 Ahlsell- Holmenga | F36: Nebbenes | G36: 52768 | H36: =11117-70 -> 11047 | P36: Ferdig | Q36: 29786500 | R36: 0.1369 | S36: =Q36*R36 -> 4077771.8 | T36: =Q36/G36 -> 564.48037 | U36: =IF(A36="","",(A36+60)) -> 45291 | V36: 44995 | Y36: =IF(OR(P36="Ordre",P36="Ferdig"),"x","") -> x | Z36: =IF(P36="Ferdig","x","") -> x | AA36: =IF(P36="Tapt","x","")
A37: 44966 | B37: HSK | C37: Straye Stålbygg AS | D37: 23016 Stansefabrikken | F37: Fredrikstad | G37: 3247 | I37: SEPTEMBER | P37: Ferdig | Q37: 1992370 | R37: 0.1882 | S37: =Q37*R37 -> 374964.03 | T37: =Q37/G37 -> 613.60333 | U37: =IF(A37="","",(A37+60)) -> 45026 | V37: 44995 | W37: SB møte med Holmskau uke 11. | Y37: =IF(OR(P37="Ordre",P37="Ferdig"),"x","") -> x | Z37: =IF(P37="Ferdig","x","") -> x | AA37: =IF(P37="Tapt","x","")
A38: 45035 | B38: HSK | C38: Thermica AS | D38: 23018 Holtskogen Plastretur | F38: Tomter | G38: 12585 | P38: Tapt | Q38: 5727475 | R38: 0.245 | S38: =Q38*R38 -> 1403231.4 | T38: =Q38/G38 -> 455.1033 | U38: =IF(A38="","",(A38+60)) -> 45095 | W38: Entreprenør ikke valgt. Thermica- Sondre Følg opp!!! | X38: 1 | Y38: =IF(OR(P38="Ordre",P38="Ferdig"),"x","") | Z38: =IF(P38="Ferdig","x","") | AA38: =IF(P38="Tapt","x","") -> x
A39: 45089 | B39: HSK | C39: Straye Stålbygg AS | D39: 23019 Osloveien 624 | F39: Enebakk | G39: 528 | H39: =137 -> 137 | P39: Ferdig | Q39: 449000 | R39: 0.2283 | S39: =Q39*R39 -> 102506.7 | T39: =Q39/G39 -> 850.37879 | U39: =IF(A39="","",(A39+60)) -> 45149 | V39: 44995 | W39: SB møte med Holmskau uke 11 | Y39: =IF(OR(P39="Ordre",P39="Ferdig"),"x","") -> x | Z39: =IF(P39="Ferdig","x","") -> x | AA39: =IF(P39="Tapt","x","")
A40: 44971 | B40: HSK | C40: Betonmast Romerike | D40: 23020 Møller BT2 | F40: Gardermoen | G40: 3170 | P40: Ferdig | Q40: 2350000 | R40: 0.1696 | S40: =Q40*R40 -> 398560 | T40: =Q40/G40 -> 741.32492 | U40: =IF(A40="","",(A40+60)) -> 45031 | Y40: =IF(OR(P40="Ordre",P40="Ferdig"),"x","") -> x | Z40: =IF(P40="Ferdig","x","") -> x | AA40: =IF(P40="Tapt","x","")
...

Sheet Serviceavtaler
C3: Sericeavtaler Straye tak 2025
C7: Adresse | G7: Avtale | I7: Dato | L7: Kontakt | O7: Mailadresse | S7: Tlf.nr | U7: Komentar | X7: mnd | Z7: Årlig pris | AB7: Status
C10: Akersgaten 45, 0158 Oslo | G10: Backegården DA (Malling &co) | I10: 42619 | L10: Alan Gardi | O10: alan.gardi@malling.no | S10: 924 94 725 | X10: Juni | Z10: 7800 | AB10: Utført2025
C13: Bergrådveien 5 0873 Oslo | G13: Eierseksjonssameiet | I13: 43052 | L13: Elisabeth Febjør | O13: b5@styrerommet.no | S13: 924 12 428 | X13: august | Z13: 10900 | AB13: Utført2025
G14: Bergrådveien 5
B16: Avsluttet | C16: Frysjaveien 35 0884 Oslo | G16: Malling & co | I16: 43372 | L16: Arild Sørensen | O16: arild.sorensen@mallingCO.NO | S16: 488 90 316 | X16: august | Z16: 5339 | AB16: Ikke utført2025
C19: Haugerskolevei 50 1351 Rud | G19: Hauger park Boligsameie | I19: 42909 | L19: Thorleif Karlsen | O19: thorleifka@gmail.com | S19: 470 25 028 | X19: august | Z19: 10132 | AB19: Utført2025
C22: Heimansåsen 11 3470 Slemmestad | G22: Heimansåsen BRL | I22: 42703 | L22: Tor inge skoglund | O22: tor.inge.skoglund@ibis.no | S22: 951 78 465 | X22: juli | Z22: 7800 | AB22: Utført2025
G23: 5-7-9-11
B25: Avsluttet | C25: Bygdøy Alle 92 a-b 0273 Oslo | G25: Sameiet Bygdøy alle 92 | I25: 42674 | L25: Joakim de borda | O25: joakim.borda@gmail.com | S25: 412 88 607 | X25: juli | Z25: 12800 | AB25: Ikke utført2025
C28: Kjørebokollen 19-29 1337 Sandvika | G28: Sameiet kjørbokollen 19.29 | I28: 43039 | L28: Homan Randarzan | O28: randarzan@hotmail.com | S28: 917 22 913 | W28: November | X28: September | Z28: 12800 | AB28: Utført2025
B31: Avsluttet | C31: Kirsten flagstads plass 1 0150 Oslo | G31: Statsbygg operan | I31: 43271 | L31: Aleksander Furulund | O31: aleksander.furulund.swedhs@statsbygg.no | S31: 481 99 012 | X31: august | Z31: 12155 | AB31: Ikke utført2025
C34: Sinsenveien 55 0585 Oslo | G34: Thormod skogstad | I34: 43132 | L34: Thormor Skogstad | O34: thormod.skogstad@gmail.com | S34: 906 91 185 | X34: august | Z34: 4800 | AB34: Utført2025
G35: Hvalsodden 29 1394 Nesbru
B37: Avsluttet | C37: Støperiveien 5 2010 Strømmen | G37: Vats AS | I37: 42885 | L37: Ole Herredsvela | O37: ole.herredsvela@strommenstorsenter.no | S37: 909 51 051 | X37: august | Z37: 83256 | AB37: Ikke utført2025
C40: Inga Bjørnsonsvei 78 0669 Oslo | G40: Vestliterrassen boligsamei | I40: 43364 | L40: Mai H Gidske | O40: maihe@online.no | S40: 959 36 450 | X40: September | Z40: 7800 | AB40: Utført2025
C43: Masteveien 6 1481 Hagan | G43: Ga-meknett | I43: 42663 | L43: Arild Willersrud | O43: arild@gassarmatur.no | S43: 415 08 815 | X43: Juni | Z43: 12800 | AB43: Utført2025
C46: Otto ruges vei 81 1332 Østerås | G46: Østeråsboliger 1 | I46: 38492 | L46: Pål Fritzon | O46: pal@fritzon.as | S46: 916 33 130 | X46: august | Z46: 13800 | AB46: Utført2025
C49: Tidemansgate 28 Oslo | G49: Tidemansgate 28a-b | I49: 44713 | L49: Henning Stene | O49: henning@stene.as | S49: 922 57 900 | X49: September | Z49: 10800 | AB49: Utført2025
C52: Strømsveien 93 Strømmen | G52: Strømmen terrasse sameiet | I52: 02.08.0222 | L52: Arild Ingebretsen | O52: ai@washify.no | S52: 908 84 000 | X52: august | Z52: 14800 | AB52: Utført2025
C55: Kittel-nilsensvei 59 | G55: Sameiet kittel nielsensvei 59 | I55: 44774 | L55: Terje Overgård | O55: tovergaa@online.no | S55: 907 87 905 | U55: Annen hver år | V55: 2026 | X55: august | Z55: 12800 | AB55: Ikke utført2025
C58: Pareliusveien 2-4 | G58: Pareliusveien 2-4 | I58: 44789 | L58: Per Berntzen | O58: barbros1@getmail.no | S58: 924 54 400 | U58: Ny styreleder | X58: august | Z58: 12800 | AB58: Utført2025
C61: Plogveien 22 | G61: Oslobygg Kf | I61: 44844 | L61: Vebjærn Are Olsen | O61: vebjorn.olsen@obf.oslo.kommune.no | S61: 99085638 | X61: September | Z61: 10800 | AB61: Utført2025
C64: Hellerudparken | G64: Hellerudparken | I64: 45944 | L64: Styreleder | O64: hellerudparken@styrerommet.no | S64: 932 04 447 | X64: September | Z64: 14800 | AB64: Utført2025
C67: Møllergata 50-52 | G67: Møllergata 50-52 | I67: 45058 | L67: Bjørn Grenager | O67: fredensborg1@styrerommet.no | S67: 991 64 418 | X67: august | Z67: 14560 | AB67: Utført2025
O68: Vaktmester Rolf | S68: 970 26 794
C70: Søndre skrenten | G70: Søndre skrenten | I70: 45086 | L70: Tale Kristin Skeidsvoll | O70: sondreskrenten3@styrerommet.no | S70: 957 64 730 | X70: august | Z70: 12800 | AB70: Utført2025
C73: Rådhusplass 333 1531 Moss | G73: Boligsameiet Rådhusplass | I73: 27.04.20213 | L73: Rune Finvold | O73: rune.finvold@fpc.no | S73: 900 96 515 | X73: September | Z73: 14800 | AB73: Utført2025
C76: Sameiet Nordengveien 2 | G76: Nordengveien 2 | I76: 45197 | L76: Sverre Haider | O76: shaider@online.no | S76: 906 5 4711 | U76: Annen vært år | X76: September | Z76: 11800 | AB76: Ikke utført2025
C79: Rygge Seniortun Boligsameie | G79: Goenveien 4 | I79: 45516 | L79: Ole H Devle | O79: ohdevle@online.no | S79: 997 02 327 | X79: Juli | Z79: 8289 | AB79: Utført2025
C82: Rygge Seniorbo | G82: Goenveien 2 | I82: 45552 | L82: Hans Tofterå | O82: hans2501@gmail.com | S82: 951 41 301 | X82: august | Z82: 13800 | AB82: Utført2025
C85: Oslo Kommune | G85: Trondheimsveien 233 | I85: 45146 | L85: Stig Audun Motzfeldt | O85: stig.motzfeldt@obf.oslo.kommune.no | S85: 402 00 132 | X85: September | Z85: 14800 | AB85: Utført2025 | AD85: Tirsdag 4 august 2026
B88: Avsluttet | C88: Ikea Furuset | G88: Strømsveien 303 | I88: 45205 | L88: Anne Lene Hauer | O88: annelene.hauer@ingka.ikea.com | S88: 911 39 904 | X88: august | Z88: 37800 | AB88: Ikke utført2025
B91: Avsluttet | C91: Ikea furuset lager | G91: Gamle leirdalsvei 1 | I91: 45489 | L91: Nina Sjernesund | O91: nina.sjernesund@ingka.ikea.com | S91: 941 41 692 | X91: august | Z91: 23800 | AB91: Ikke utført2025
C94: Ildjernåsen | G94: Richard Baches vei 8-10 | I94: 45189 | L94: Finn Magne Spjelkavik | O94: ildjernasen@styrerommet.no | S94: 928 08 155 | X94: September | Z94: 12800 | AB94: Utført2025
C97: Sannergata 14 | G97: Valdresgata | H97: Borettslag | I97: 45224 | L97: Beate Muri | O97: styret@valdresgataborettslag.no | S97: 905 04 804 | X97: September | Z97: 10800 | AB97: Utført2025
C100: Refstadveien 32 | G100: Panorama Sameie | I100: 45470 | L100: Dagfinn Bakke | O100: bjerkepanorama@gmail.com | S100: 411 05 332 | X100: august | Z100: 12800 | AB100: Utført2025
C103: Hoffsgrenda Borettslag | G103: Skøyen Terrasse 2- 29 | I103: 46113 | L103: Vaktmester | O103: fredrikhogestol@gmail.com | S103: 480 88 634 | U103: Høst,vår | V103: 2 ganger | X103: September | Z103: 22400 | AB103: Ikke utført2025 | AD103: Starter 2026
C105: Hyllebærstien Borettslag | G105: Hyllebærstien 1405 Langhus | I105: 45786 | L105: Stig Lambertsen | O105: hyllebaerstienborettslag@mittusbl.no | S105: 925 54 873 | X105: August | Z105: 12800 | AB105: Utført2025
C107: Bjørnstadtunet 1 | E107: Fredrikstad | G107: Hovedtunet Boligsameie | I107: 45888 | L107: Svein Mathiesen | O107: svein@sveinmathiesen.no | U107: Låst sumi 3 år | X107: Mai | Z107: 16800 | AB107: Ikke utført2025 | AD107: Starter 2026
...

Sheet Prosjektplan
A1: Sjekkliste
D2: Dagens dato | E2: =TODAY() -> 46001
D4: AKTUELL UKE | E4: =_xlfn.ISOWEEKNUM(E2) -> 50
A6: P. nr. | B6: Prosjektnavn | C6: Oppdragsgiver | D6: PL Stål | E6: Oppstart uke | F6: Handover levert | G6: Bekr./ kontrakt | H6: Erklært ansvarsrett | I6: Avkl. Løsning PIR/ MU | J6: Sluk plassering / isolering av sluk | K6: Isolering av innside gesims | L6: Beregnet festemidler | M6: Tegning/ prosj | N6: Best. Diffsperre | O6: Best. PIR | P6: Best. MU | Q6: Best. Festemidler | R6: Festem. PIR skinner, gesims | S6: Best. Sluk | T6: Bestilt PVC/ ATB | U6: Bestilt sikring | V6: Bestilt Permanent taksikring | W6: Bestilt kran | X6: KS | Y6: FDV | Z6: Overtakelse | AA6: Ferdig hittil | AB6: Andel ferdig | AC6: Avsluttet | AD6: Kommentarer
B7: Filterlinje
A8: 22001 | B8: Apilar | C8: Hallgruppen AS | D8: Jan Fredrik | E8: 1 | F8: IA | G8: 1 | H8: 1 | I8: 1 | J8: 1 | K8: IA | L8: 1 | M8: 1 | N8: 1 | O8: 1 | P8: 1 | Q8: 1 | R8: 1 | S8: 1 | T8: 1 | U8: 1 | V8: 1 | W8: 1 | X8: 1 | Y8: 1 | Z8: 1 | AA8: =IF(B8="","",(COUNTA(F8:Z8))) -> 21 | AB8: =IF(B8="","",(AA8/COUNTA($F$6:$Z$6))) -> 1 | AC8: x | AD8: Overta siste takoverbygg
A9: 22003 | B9: Aurevegen 2 | C9: Hallgruppen AS | D9: Tommy | E9: 8 | F9: IA | G9: 1 | H9: 1 | I9: 1 | J9: 1 | K9: 1 | L9: 1 | M9: 1 | N9: 1 | O9: 1 | P9: 1 | Q9: 1 | R9: 1 | S9: IA | T9: 1 | U9: 1 | V9: 1 | W9: 1 | X9: 1 | Y9: 1 | Z9: 1 | AA9: =IF(B9="","",(COUNTA(F9:Z9))) -> 21 | AB9: =IF(B9="","",(AA9/COUNTA($F$6:$Z$6))) -> 1 | AC9: x | AD9: HUSK ISOLASJON I TRP VED KLIMAVEGG. Oppstart uke 8??. 4200 til PIR
A10: 22006 | B10: Ihlen Lager | C10: Straye Stålbygg | D10: Frode | E10: 12 | F10: IA | G10: 1 | H10: 1 | I10: 1 | J10: 1 | K10: IA | L10: 1 | M10: 1 | N10: 1 | O10: 1 | P10: 1 | Q10: 1 | R10: 1 | S10: 1 | T10: 1 | U10: 1 | V10: 1 | W10: 1 | X10: 1 | Y10: 1 | Z10: 1 | AA10: =IF(B10="","",(COUNTA(F10:Z10))) -> 21 | AB10: =IF(B10="","",(AA10/COUNTA($F$6:$Z$6))) -> 1 | AC10: x
A11: 22002 | B11: Killingmo | C11: Hallgruppen AS | D11: Tommy | E11: 13 | F11: IA | G11: 1 | H11: 1 | I11: 1 | J11: 1 | K11: 1 | L11: 1 | M11: 1 | N11: 1 | O11: 1 | P11: 1 | Q11: 1 | R11: 1 | S11: IA | T11: 1 | U11: 1 | V11: 1 | W11: 1 | X11: 1 | Y11: 1 | Z11: 1 | AA11: =IF(B11="","",(COUNTA(F11:Z11))) -> 21 | AB11: =IF(B11="","",(AA11/COUNTA($F$6:$Z$6))) -> 1 | AC11: x
A12: 22010 | B12: Kolbotn Tennishall | C12: Straye Stålbygg | D12: Jan Fredrik | E12: 42 | F12: IA | G12: IA | H12: 1 | I12: 1 | J12: 1 | K12: IA | L12: 1 | M12: 1 | N12: 1 | O12: 1 | P12: 1 | Q12: 1 | R12: 1 | S12: 1 | T12: 1 | U12: 1 | V12: 1 | W12: 1 | X12: 1 | Y12: 1 | Z12: IA | AA12: =IF(B12="","",(COUNTA(F12:Z12))) -> 21 | AB12: =IF(B12="","",(AA12/COUNTA($F$6:$Z$6))) -> 1 | AC12: x
A13: 22014 | B13: Ordfører Utnes vei 51 | C13: Holmskau Prosjekt | D13: Tommy | E13: 26 | F13: IA | G13: 1 | H13: 1 | I13: 1 | J13: 1 | K13: 1 | L13: 1 | M13: 1 | N13: 1 | O13: 1 | P13: 1 | Q13: 1 | R13: 1 | S13: 1 | T13: 1 | U13: 1 | V13: 1 | W13: 1 | X13: 1 | Y13: 1 | Z13: IA | AA13: =IF(B13="","",(COUNTA(F13:Z13))) -> 21 | AB13: =IF(B13="","",(AA13/COUNTA($F$6:$Z$6))) -> 1 | AC13: x | AD13: Røyklukker, 0 kr, inkl.
A14: 22015 | B14: Coop Ørebekk | C14: Straye Stålbygg | D14: Jon S | E14: =Prosjektliste_Prodplan!H15 -> 46 | F14: IA | G14: 1 | H14: 1 | I14: 1 | J14: 1 | K14: 1 | L14: 1 | M14: 1 | N14: 1 | O14: 1 | P14: 1 | Q14: 1 | R14: 1 | S14: 1 | T14: 1 | U14: 1 | V14: IA | W14: 1 | X14: 1 | Y14: 1 | Z14: 1 | AA14: =IF(B14="","",(COUNTA(F14:Z14))) -> 21 | AB14: =IF(B14="","",(AA14/COUNTA($F$6:$Z$6))) -> 1 | AC14: x | AD14: 50% av MU
A15: 22019 | B15: Skjeberg Marinesenter | C15: Straye Stålbygg | D15: Jon | E15: 45 | F15: IA | G15: IA | H15: IA | I15: 1 | J15: 1 | K15: IA | L15: 1 | M15: 1 | N15: 1 | O15: 1 | P15: 1 | Q15: 1 | R15: 1 | S15: 1 | T15: 1 | U15: 1 | V15: 1 | W15: 1 | X15: 1 | Y15: 1 | Z15: IA | AA15: =IF(B15="","",(COUNTA(F15:Z15))) -> 21 | AB15: =IF(B15="","",(AA15/COUNTA($F$6:$Z$6))) -> 1 | AC15: x
A16: 22025 | B16: Dekkhotell Røyken | C16: Hallgruppen AS | D16: Christian FL | E16: 28 | F16: IA | G16: 1 | H16: 1 | I16: 1 | J16: 1 | K16: 1 | L16: 1 | M16: 1 | N16: 1 | O16: 1 | P16: 1 | Q16: 1 | R16: 1 | S16: 1 | T16: 1 | U16: 1 | V16: 1 | W16: 1 | X16: 1 | Y16: 1 | Z16: 1 | AA16: =IF(B16="","",(COUNTA(F16:Z16))) -> 21 | AB16: =IF(B16="","",(AA16/COUNTA($F$6:$Z$6))) -> 1 | AC16: x
A17: 23002 | B17: Asko Oslofjord | C17: Straye Stålbygg | D17: Christian FL | E17: 1 | F17: IA | G17: 1 | H17: 1 | I17: 1 | J17: 1 | K17: IA | L17: 1 | M17: 1 | N17: 1 | O17: 1 | P17: 1 | Q17: 1 | R17: 1 | S17: 1 | T17: 1 | U17: 1 | V17: 1 | W17: 1 | X17: 1 | Y17: 1 | Z17: 1 | AA17: =IF(B17="","",(COUNTA(F17:Z17))) -> 21 | AB17: =IF(B17="","",(AA17/COUNTA($F$6:$Z$6))) -> 1 | AC17: x | AD17: Avtalt overtatt med Christian F L
A18: 23016 | B18: Stansefabrikken/ Bjørnstadgrenda | C18: Holmskau Prosjekt | D18: Tommy | E18: 40 | F18: IA | G18: IA | H18: 1 | I18: 1 | J18: 1 | K18: IA | L18: 1 | M18: 1 | N18: 1 | O18: 1 | P18: 1 | Q18: 1 | R18: 1 | S18: 1 | T18: 1 | U18: 1 | V18: IA | W18: 1 | X18: 1 | Y18: 1 | Z18: IA | AA18: =IF(B18="","",(COUNTA(F18:Z18))) -> 21 | AB18: =IF(B18="","",(AA18/COUNTA($F$6:$Z$6))) -> 1 | AC18: x | AD18: KINGSPAN PIR grunnet EPD for Breeam, 1,5 mm foil
A19: 23019 | B19: Osloveien 624 | C19: Holmskau Prosjekt | D19: Geir N/ Jan Fredrik | E19: 6 | F19: IA | G19: 1 | H19: IA | I19: 1 | J19: 1 | K19: 1 | L19: 1 | M19: 1 | N19: 1 | O19: 1 | P19: 1 | Q19: 1 | R19: 1 | S19: 1 | T19: 1 | U19: 1 | V19: IA | W19: 1 | X19: 1 | Y19: 1 | Z19: IA | AA19: =IF(B19="","",(COUNTA(F19:Z19))) -> 21 | AB19: =IF(B19="","",(AA19/COUNTA($F$6:$Z$6))) -> 1 | AC19: x
A20: 23020 | B20: Møller Bil BT2 | C20: Betonmast | D20: Jon | E20: 23 | F20: IA | G20: IA | H20: 0.1 | I20: 1 | J20: 1 | K20: 1 | L20: 1 | M20: 1 | N20: 1 | O20: 1 | P20: 1 | Q20: 1 | R20: 1 | S20: 1 | T20: 1 | U20: 1 | V20: 1 | W20: 1 | X20: 1 | Y20: 1 | Z20: IA | AA20: =IF(B20="","",(COUNTA(F20:Z20))) -> 21 | AB20: =IF(B20="","",(AA20/COUNTA($F$6:$Z$6))) -> 1 | AC20: x
A21: 23005 | B21: Posten Moss | C21: Straye Stålbygg AS | D21: Salmir | E21: 21 | F21: IA | G21: 1 | H21: 0 | I21: 1 | J21: 1 | K21: 1 | L21: 1 | M21: 1 | N21: 1 | O21: 1 | P21: 1 | Q21: 1 | R21: 1 | S21: 1 | T21: 1 | U21: 1 | V21: 1 | W21: 1 | X21: 1 | Y21: 1 | Z21: 1 | AA21: =IF(B21="","",(COUNTA(F21:Z21))) -> 21 | AB21: 1 | AC21: x
A22: 23014 | B22: Ahlsell- Holmenga | C22: Straye Stålbygg AS | D22: Jan Fredrik | E22: 22 | F22: IA | G22: 1 | H22: IA | I22: 1 | J22: 1 | K22: 1 | L22: 1 | M22: 1 | N22: 1 | O22: 1 | P22: 1 | Q22: 1 | R22: 1 | S22: 1 | T22: 1 | U22: 1 | V22: 1 | W22: 1 | X22: 1 | Y22: 1 | Z22: 1 | AA22: =IF(B22="","",(COUNTA(F22:Z22))) -> 21 | AB22: =IF(B22="","",(AA22/COUNTA($F$6:$Z$6))) -> 1 | AC22: x
A23: 23038 | B23: Bulk Wood | C23: Thermica AS | D23: Christian FL | E23: 36 | F23: IA | G23: 1 | H23: 1 | I23: 1 | J23: 1 | K23: 1 | L23: 1 | M23: 1 | N23: 1 | O23: 1 | P23: 1 | Q23: 1 | R23: 1 | S23: 1 | T23: 1 | U23: 1 | V23: 1 | W23: 1 | X23: 1 | Y23: 1 | Z23: IA | AA23: =IF(B23="","",(COUNTA(F23:Z23))) -> 21 | AB23: =IF(B23="","",(AA23/COUNTA($F$6:$Z$6))) -> 1 | AC23: x | AD23: Kingspan tre konstruksjon og TG
A24: 23040 | B24: Trondheimsveien 183- Vaskehall | C24: Straye Stålbygg | D24: Christian FL | E24: 27 | F24: IA | G24: IA | H24: IA | I24: 1 | J24: 1 | K24: IA | L24: 1 | M24: 1 | N24: 1 | O24: 1 | P24: 1 | Q24: 1 | R24: 1 | S24: 1 | T24: 1 | U24: 1 | V24: IA | W24: 1 | X24: 1 | Y24: 1 | Z24: 1 | AA24: =IF(B24="","",(COUNTA(F24:Z24))) -> 21 | AB24: =IF(B24="","",(AA24/COUNTA($F$6:$Z$6))) -> 1 | AC24: x
A25: 23043 | B25: Rema1000 Ørebekk | C25: Straye Stålbygg | D25: Christian FL | E25: 50 | F25: IA | G25: 1 | H25: IA | I25: 1 | J25: 1 | K25: 1 | L25: 1 | M25: 1 | N25: 1 | O25: 1 | P25: 1 | Q25: 1 | R25: 1 | S25: 1 | T25: 1 | U25: 1 | V25: 1 | W25: 1 | X25: IA | Y25: 1 | Z25: IA | AA25: =IF(B25="","",(COUNTA(F25:Z25))) -> 21 | AB25: =IF(B25="","",(AA25/COUNTA($F$6:$Z$6))) -> 1 | AC25: x
A26: 23049 | B26: Tilbygg Coop Manstad | C26: Straye Stålbygg | D26: Tommy | E26: 43 | F26: IA | G26: IA | H26: 1 | I26: 1 | J26: 1 | K26: 1 | L26: 1 | M26: 1 | N26: 1 | O26: 1 | P26: 1 | Q26: 1 | R26: 1 | S26: 1 | T26: 1 | U26: 1 | V26: 1 | W26: 1 | X26: 1 | Y26: 1 | Z26: IA | AA26: =IF(B26="","",(COUNTA(F26:Z26))) -> 21 | AB26: =IF(B26="","",(AA26/COUNTA($F$6:$Z$6))) -> 1 | AC26: x
A27: 23050 | B27: Kvadratera | C27: Hallgruppen AS | D27: Tommy | E27: 47 | F27: IA | G27: IA | H27: IA | I27: 1 | J27: 1 | K27: 1 | L27: 1 | M27: 1 | N27: 1 | O27: 1 | P27: 1 | Q27: 1 | R27: 1 | S27: 1 | T27: 1 | U27: 1 | V27: IA | W27: 1 | X27: 1 | Y27: 1 | Z27: IA | AA27: =IF(B27="","",(COUNTA(F27:Z27))) -> 21 | AB27: =IF(B27="","",(AA27/COUNTA($F$6:$Z$6))) -> 1 | AC27: x
A28: 23053 | B28: Reolteknikk | C28: Hallgruppen AS | D28: Christian FL | E28: 4 | F28: IA | G28: 1 | H28: 1 | I28: 1 | J28: 1 | K28: 1 | L28: 1 | M28: 1 | N28: 1 | O28: Kingspan | P28: 1 | Q28: 1 | R28: 1 | S28: 1 | T28: 1 | U28: 1 | V28: IA | W28: 1 | X28: 1 | Y28: 1 | Z28: 1 | AA28: =IF(B28="","",(COUNTA(F28:Z28))) -> 21 | AB28: =IF(B28="","",(AA28/COUNTA($F$6:$Z$6))) -> 1 | AC28: x
A29: 23057 | B29: Lafinto | C29: Holmskau Prosjekt | D29: Tommy | E29: =Prosjektliste_Prodplan!H29 -> 4 | F29: IA | G29: 1 | H29: 1 | I29: 1 | J29: 1 | K29: 1 | L29: 1 | M29: 1 | N29: 1 | O29: 1 | P29: 1 | Q29: 1 | R29: 1 | S29: 1 | T29: 1 | U29: 1 | V29: 1 | W29: 1 | X29: 1 | Y29: 1 | Z29: IA | AA29: =IF(B29="","",(COUNTA(F29:Z29))) -> 21 | AB29: =IF(B29="","",(AA29/COUNTA($F$6:$Z$6))) -> 1 | AC29: x
A30: 23068 | B30: Thaugland- Bjørnerudveien 16 | C30: Straye Stålbygg | D30: Frode | E30: 7 | F30: IA | G30: IA | H30: 1 | I30: 1 | J30: 1 | K30: IA | L30: 1 | M30: 1 | N30: 1 | O30: 1 | P30: 1 | Q30: 1 | R30: 1 | S30: 1 | T30: 1 | U30: 1 | V30: IA | W30: 1 | X30: 1 | Y30: 1 | Z30: 1 | AA30: =IF(B30="","",(COUNTA(F30:Z30))) -> 21 | AB30: =IF(B30="","",(AA30/COUNTA($F$6:$Z$6))) -> 1 | AC30: x
A31: 23023 | B31: Asko Oslofjord Miljøstasjon | C31: Straye Stålbygg | D31: Frode | E31: 37 | F31: IA | G31: IA | H31: 1 | I31: 1 | J31: 1 | K31: IA | L31: 1 | M31: 1 | N31: 1 | O31: 1 | P31: 1 | Q31: 1 | R31: 1 | S31: 1 | T31: 1 | U31: 1 | V31: 1 | W31: 1 | X31: 1 | Y31: 1 | Z31: 1 | AA31: =IF(B31="","",(COUNTA(F31:Z31))) -> 21 | AB31: =IF(B31="","",(AA31/COUNTA($F$6:$Z$6))) -> 1 | AC31: x | AD31: BAUDER grunnet asfalt, se premissdokument
A32: 23036 | B32: Myrveien Råde | C32: Straye Stålbygg | D32: Tommy | E32: 22 | F32: IA | H32: 1 | N32: 1 | O32: 1 | AA32: =IF(B32="","",(COUNTA(F32:Z32))) -> 4 | AB32: =IF(B32="","",(AA32/COUNTA($F$6:$Z$6))) -> 0.19047619 | AC32: x
A33: 23042 | B33: Hallingplast | C33: Straye Stålbygg ? | D33: Tommy | E33: 20 | F33: IA | G33: 1 | H33: IA | I33: 1 | J33: 1 | K33: 1 | L33: 1 | M33: 1 | N33: 1 | O33: 1 | P33: 1 | Q33: 1 | R33: 1 | S33: 1 | T33: 1 | U33: 1 | V33: 1 | W33: 1 | X33: 1 | Y33: 1 | Z33: 1 | AA33: =IF(B33="","",(COUNTA(F33:Z33))) -> 21 | AB33: =IF(B33="","",(AA33/COUNTA($F$6:$Z$6))) -> 1 | AC33: x
A34: 23054 | B34: Asian Food | C34: Straye Stålbygg AS | D34: Christian | E34: 17 | F34: IA | G34: 1 | H34: 1 | I34: 1 | J34: 1 | K34: 1 | L34: 1 | M34: 1 | N34: 1 | O34: 1 | P34: 1 | Q34: 1 | R34: 1 | S34: 1 | T34: 1 | U34: 0 | V34: 0 | W34: 1 | X34: 1 | Y34: 1 | Z34: 1 | AA34: =IF(B34="","",(COUNTA(F34:Z34))) -> 21 | AB34: =IF(B34="","",(AA34/COUNTA($F$6:$Z$6))) -> 1 | AC34: x
A35: 23055 | B35: Qmatec | C35: Straye Stålbygg AS | D35: Salmir | E35: 23 | F35: IA | G35: 1 | H35: IA | I35: 1 | J35: 1 | K35: 1 | L35: 1 | M35: 1 | N35: 1 | O35: 1 | P35: 1 | Q35: 1 | R35: 1 | S35: 1 | T35: 1 | U35: 1 | V35: 0 | W35: 1 | X35: 1 | Y35: 1 | Z35: 1 | AA35: =IF(B35="","",(COUNTA(F35:Z35))) -> 21 | AB35: =IF(B35="","",(AA35/COUNTA($F$6:$Z$6))) -> 1 | AC35: X
A36: 23073 | B36: Vestre Vanemvei | C36: Straye Stålbygg AS | D36: Tommy | E36: 22 | F36: 0 | G36: 1 | H36: 1 | I36: 1 | J36: 1 | K36: 1 | L36: 1 | M36: 1 | N36: 1 | O36: 1 | P36: 1 | Q36: 1 | R36: 1 | S36: 1 | T36: 1 | U36: 1 | V36: 1 | W36: 1 | X36: 1 | Y36: 1 | Z36: 1 | AA36: =IF(B36="","",(COUNTA(F36:Z36))) -> 21 | AB36: =IF(B36="","",(AA36/COUNTA($F$6:$Z$6))) -> 1 | AC36: X
A37: 23080 | B37: Neumann | C37: Holmskau Prosjekt | E37: 23 | G37: 1 | H37: 1 | I37: 1 | J37: 1 | K37: 1 | L37: 1 | M37: 1 | N37: 1 | O37: 1 | P37: 1 | Q37: 1 | R37: 1 | S37: 1 | T37: 1 | U37: 1 | V37: 1 | W37: 1 | AA37: =IF(B37="","",(COUNTA(F37:Z37))) -> 17 | AB37: =IF(B37="","",(AA37/COUNTA($F$6:$Z$6))) -> 0.80952381 | AC37: x
A38: 23081 | B38: Gummiservice AS | C38: Straye Stålbygg AS | D38: Tommy | E38: 20 | F38: IA | G38: 1 | H38: 1 | I38: 1 | J38: 1 | K38: 1 | L38: 1 | M38: 1 | N38: 1 | O38: 1 | P38: 1 | Q38: 1 | R38: 1 | S38: 1 | T38: 1 | U38: 1 | V38: IA | W38: 1 | X38: 1 | Y38: 1 | Z38: 1 | AA38: =IF(B38="","",(COUNTA(F38:Z38))) -> 21 | AB38: =IF(B38="","",(AA38/COUNTA($F$6:$Z$6))) -> 1 | AC38: x
A39: 23090 | B39: Atlas Gardermoen | C39: Straye Stålbygg AS | D39: Christian FL | G39: 1 | H39: 1 | I39: 1 | J39: 1 | K39: 1 | L39: 1 | M39: 1 | N39: 1 | O39: 1 | P39: 1 | Q39: 1 | R39: 1 | S39: 1 | T39: 1 | U39: 1 | V39: 1 | W39: 1 | AA39: =IF(B39="","",(COUNTA(F39:Z39))) -> 17 | AB39: =IF(B39="","",(AA39/COUNTA($F$6:$Z$6))) -> 0.80952381
A40: 23096 | B40: New Wave | C40: Straye Stålbygg | E40: 13 | F40: IA | G40: IA | H40: 1 | I40: 1 | J40: 1 | K40: IA | L40: 1 | M40: 1 | N40: 1 | O40: 1 | P40: 1 | Q40: 1 | R40: 1 | S40: 1 | T40: 1 | U40: 1 | V40: IA | W40: 1 | Z40: 1 | AA40: =IF(B40="","",(COUNTA(F40:Z40))) -> 19 | AB40: =IF(B40="","",(AA40/COUNTA($F$6:$Z$6))) -> 0.9047619 | AC40: x
A41: 23097 | B41: Høstbakken 11 | C41: Straye Stålbygg | D41: Tommy | E41: 17 | F41: IA | G41: IA | H41: IA | I41: IA | K41: IA | N41: 1 | O41: 1 | Q41: 1 | R41: 1 | S41: 1 | T41: 1 | U41: 1 | V41: IA | AA41: =IF(B41="","",(COUNTA(F41:Z41))) -> 13 | AB41: =IF(B41="","",(AA41/COUNTA($F$6:$Z$6))) -> 0.61904762 | AC41: x
A42: 23100 | B42: Atracco Arendal | C42: Straye Stålbygg | D42: Frode?? | E42: 25?? | F42: IA | AA42: =IF(B42="","",(COUNTA(F42:Z42))) -> 1 | AB42: =IF(B42="","",(AA42/COUNTA($F$6:$Z$6))) -> 0.047619048 | AC42: x
...

Sheet Folie-skruer
A2: 1.6 | B2: 20 | C2: =A2*B2 -> 32
A3: 1.59 | B3: 19.9 | C3: =A3*B3 -> 31.641
A5: Areal midtfelt | C5: 572
A7: Antall ruller | C7: =C5/C3 -> 18.07781 | T7: 106
T8: 43
T9: 53
T10: 29
T11: 35
T12: 23
T13: 30
T14: 32
A15: Skruer PIR | B15: 1.2 | T15: 33
B16: 2.4 | T16: 35
B17: =B16*B15 -> 2.88 | T17: 5
A18: Skruer PIR | B18: 5 | C18: stk | T18: 11
B19: =B18/B17 -> 1.7361111 | C19: Skruer /m² | E19: Tak 1-3
D20: Ihlen lager | E20: Best
A21: Areal | B21: =1050+1200+1100 -> 3350 | T21: =SUM(T7:T20) -> 435
A22: Ant. Skruer | B22: =B21*B19 -> 5815.9722 | E22: 6000
T23: 303
A24: Skiver PIR | B24: =B22 -> 5815.9722 | E24: =E22 -> 6000
T26: =T21-T23 -> 132
A29: Skruer list | K29: Messa
A30: Pr. meter | B30: 3.2 | K30: 0,18 MU gjennomgående
A31: Antal m | B31: =52+48+22+22+20+2+22+12+22+18 -> 240 | K31: 1550
A32: Antall skruer | B32: =B30*B31 -> 768 | E32: 1000 | K32: 1100000
K34: =K32/K31 -> 709.67742
A35: Skruer list
A36: Pr. meter | B36: 3.2
A37: Antal m | B37: =32+44+44+44+60 -> 224
A38: Antall skruer | B38: =B36*B37 -> 716.8 | E38: 1000
A41: Skruer REIM isol
A42: Pr. meter | B42: 5
A43: Antal m | B43: =32+44+44+44+60 -> 224
A44: Antall skruer | B44: =B42*B43 -> 1120 | E44: 1000
A46: Skive gesimsisol | B46: =B44 -> 1120 | E46: =E44 -> 1000

Sheet Akkord 2025
H1: Januar
K4: 24115 Mosseveien 104
L5: Timer | M5: Andel | N5: Beløp
K6: 2. Michal Pastor | L6: 26 | M6: 0.72222222 | N6: 2648.1739 | O6: BAS
K7: 14. Grzegorz Legutko | L7: 5 | M7: 0.13888889 | N7: 938.1183 | O7: OM
K8: 27. Pawel Ulikowski | L8: 5 | M8: 0.13888889 | N8: 509.26422
H12: Februar
K15: 23014 Ahlsell Eidsvoll
L16: Timer | M16: Andel | N16: Beløp
K17: 14. Grzegorz Legutko | L17: 188 | M17: 0.15052042 | N17: 11631.545
K18: 15. Marek Legutko | L18: 250.5 | M18: 0.20056045 | N18: 8303.2026
K19: 26. Konrad Legutko | L19: 250.5 | M19: 0.20056045 | N19: 8303.2026
K20: 27. Pawel Ulikowski | L20: 252.5 | M20: 0.20216173 | N20: 8369.4956
K21: 34. Julia Ulikowska | M21: 0 | N21: 3000
K22: 35. Patryk Janik | M22: 0 | N22: 3000
H25: Februar
K28: 23005 Posten moss -02 EM 2 Tekking skjermtak
N29: Beløp
K30: 33. Dariusz Nowakowski | N30: 5000
K31: 30. Damian Nowaczyk | N31: 5000
K32: 29. Adam Grygorcewicz | N32: 5000
H35: Februar
A37: 24038 Starco Gardermoen
K39: 24038 Starco Gardermoen | O39: DEL 1 | P39: 28.10-01.12
L40: Timer | M40: Andel | N40: Beløp
K41: 14. Grzegorz Legutko | L41: 0 | M41: 0 | N41: 5967 | O41: OM
K42: 19. Kacper Modrzejewski | L42: 74.475 | M42: 0.1 | N42: 6328 | P42: 85
K43: XY. Straye Tak | L43: 179.5 | M43: 0 | N43: -
K44: 29. Adam Grygorcewicz | L44: 124.5 | M44: 0.17 | N44: 15579
K45: 30. Damian Nowaczyk | L45: 104 | M45: 0.14 | N45: 17193 | O45: BAS
K46: 33. Dariusz Nowakowski | L46: 177 | M46: 0.24 | N46: 20039
H51: Februar
B53: 24055 Stamas | K53: 24055 Stamas
K55: Bonus for god jobb
K57: 29. Adam Grygorcewicz | N57: 8000
K58: 30. Damian Nowaczyk | N58: 8000
H60: Februar
K63: 24125 Killingmo verksted | M63: Beløp
K64: 14. Grzegorz Legutko | M64: 2000
H69: Februar
...

Sheet Akkord 2024
H1: JANUAR
K3: 23043 Rema1000 Ørebekk
L4: Timer | M4: Andel | N4: Beløp
K5: 2. Michal Pastor | L5: 137.5 | M5: 0.12971698 | N5: 3327.2406
K6: 4. Daniel Karolczak | L6: 158 | M6: 0.1490566 | N6: 3823.3019
K7: 6. Sebastian Roszuk | L7: 141.5 | M7: 0.13349057 | N7: 3424.033
K8: 19. Kacper Modrzejewski | L8: 141.5 | M8: 0.13349057 | N8: 3424.033
K9: 20. Jakub Narloch | L9: 138.5 | M9: 0.13066038 | N9: 3351.4387
K10: 22. Grzegorz Wawrzeniec | L10: 209.5 | M10: 0.19764151 | N10: 6419.5047 | O10: BAS
K11: 23. Grzegorz Cwiklak | L11: 133.5 | M11: 0.1259434 | N11: 3230.4481
K12: 14. Grzegorz Legutko | L12: om | M12: om | N12: 3000 | O12: OM
L13: 1060 | N13: 30000
H19: JANUAR
K21: 23042 Hallingplast
L22: Timer | M22: Andel | N22: Beløp
K23: 15. Marek Legutko | L23: 161.5 | M23: 0.22555866 | N23: 19254.547
K24: 16. Krzysztof Legutko | L24: 115 | M24: 0.16061453 | N24: 13710.668
K25: 17. Krystian Wichrowski | L25: 217.5 | M25: 0.30377095 | N25: 30423.878 | O25: BASS
K26: 26. Konrad Legutko | L26: 161.5 | M26: 0.22555866 | N26: 19254.547
K27: 25. Konrad Wichrowski | L27: 60.5 | M27: 0.084497207 | N27: 7213.0036
K28: 14. Grzegorz Legutko | L28: om | M28: om | N28: 9984.0715 | O28: OM
L33: 716 | M33: 1 | N33: 99840.715
H37: FEBRUAR
K39: 23068 Thaugland Bjørnerudveien 16
L40: Timer | M40: Andel | N40: Beløp
K41: 6. Sebastian Roszuk | L41: - | M41: - | N41: -
K42: 14. Grzegorz Legutko | L42: 25 | M42: 0.13888889 | N42: 5199.3343 | O42: OM
K43: 15. Marek Legutko | L43: 19.5 | M43: 0.10833333 | N43: 3271.1241 | O43: BASS
K44: 16. Krzysztof Legutko | L44: 36 | M44: 0.2 | N44: 4064.3939
K45: 25. Konrad Wichrowski | L45: 44 | M45: 0.24444444 | N45: 4967.5926
K46: 31. Krzysztof Wojtas | L46: 36 | M46: 0.2 | N46: 4064.3939
K47: 26. Konrad Legutko | L47: 19.5 | M47: 0.10833333 | N47: 2201.5467
L51: 180 | M51: 1 | N51: 23768.385
H55: FEBRUAR
K57: 23101 Lagerseksjoner Moss & Våler bygg 1
L58: Timer | M58: Andel | N58: Beløp
K59: 14. Grzegorz Legutko | L59: 69.5 | M59: 0.34320988 | N59: 17204.174 | O59: OM
K60: 16. Krzysztof Legutko | L60: 66.5 | M60: 0.32839506 | N60: 12435.626
K61: 31. Krzysztof Wojtas | L61: 66.5 | M61: 0.32839506 | N61: 12435.626
L65: 202.5 | M65: 1 | N65: 42075.426
...

Sheet Akkord 2023
B2: November 2023
B4: 23016 Stansefabrik
B37: 22014 Ordfører Utnes vei 51

Sheet Prosjektliste_Prodplan
A1: PROSJEKTPLAN | D1: Dagens dato | E1: =TODAY() -> 46001 | L1: =-282-44-33-23-178.5-175-308-194-570 -> -1807.5
D2: AKTUELL UKE | E2: =_xlfn.ISOWEEKNUM(E1) -> 50 | L2: Akk dagsverk | M2: =M4/$E$3/$E$4 -> 0.796875 | N2: =N4/$E$3/$E$4 -> -0.078125 | O2: =O4/$E$3/$E$4 -> 0.171875 | P2: =P4/$E$3/$E$4 -> 0.171875 | Q2: =Q4/$E$3/$E$4 -> 2.671875 | R2: =R4/$E$3/$E$4 -> 1.959375 | S2: =S4/$E$3/$E$4 -> 1.603125 | T2: =T4/$E$3/$E$4 -> -0.08125 | ... BV2: =BV4/$E$3/$E$4 -> -104.75
D3: Timer pr dag | E3: 8 | L3: Akkumulert | M3: =L1+M4 -> -1775.625 | N3: =M3+N4 -> -1778.75 | O3: =N3+O4 -> -1771.875 | P3: =O3+P4 -> -1765 | Q3: =P3+Q4 -> -1658.125 | R3: =Q3+R4 -> -1579.75 | S3: =R3+S4 -> -1515.625 | T3: =S3+T4 -> -1518.875 | U3: =T3+U4 -> -1539.625 | ... BV3: =BU3+BV4 -> -14536
D4: Dager pr uke | E4: 5 | L4: Over/ under kapasitet | M4: =M5-M6 -> 31.875 | N4: =N5-N6 -> -3.125 | O4: =O5-O6 -> 6.875 | P4: =P5-P6 -> 6.875 | Q4: =Q5-Q6 -> 106.875 | R4: =R5-R6 -> 78.375 | S4: =S5-S6 -> 64.125 | T4: =T5-T6 -> -3.25 | ... BV4: =BV5-BV6 -> -4190
L5: Kapasitet timer | M5: ='Mont- Bemanning'!C3 -> 106.875 | N5: ='Mont- Bemanning'!D3 -> 106.875 | O5: ='Mont- Bemanning'!E3 -> 106.875 | P5: ='Mont- Bemanning'!F3 -> 106.875 | Q5: ='Mont- Bemanning'!G3 -> 106.875 | R5: ='Mont- Bemanning'!H3 -> 78.375 | S5: ='Mont- Bemanning'!I3 -> 64.125 | T5: ='Mont- Bemanning'!J3 -> 99.75 | ... BV5: ='Mont- Bemanning'!BL3 -> 0
D6: =SUBTOTAL(3,D9:D42) -> 29 | F6: =SUM(F9:F42) -> 28603 | G6: =SUM(G9:G42) -> 124335 | L6: Belastning | M6: =SUM(M9:M42) -> 75 | N6: =SUM(N9:N42) -> 110 | O6: =SUM(O9:O42) -> 100 | P6: =SUM(P9:P42) -> 100 | Q6: =SUM(Q9:Q42) -> 0 | R6: =SUM(R9:R42) -> 0 | S6: =SUM(S9:S42) -> 0 | T6: =SUM(T9:T42) -> 103 | ... BV6: =SUM(BV9:BV42) -> 4190
A7: P. nr. | B7: Ferdig | C7: Prosjektnavn | D7: Oppdragsgiver | E7: PL | F7: Kalk timer | G7: m² | H7: Start uke | I7: Slutt uke | J7: Planlagt | K7: Overført neste år | L7: Kontroll | M7: 1 | N7: 2 | O7: 3 | P7: 4 | Q7: 5 | R7: 6 | S7: 7 | T7: 8 | U7: 9 | V7: 10 | W7: 11 | X7: 12 | Y7: 13 | Z7: 14 | AA7: 15 | AB7: 16 | AC7: 17 | AD7: 18 | AE7: 19 | AF7: 20 | AG7: 21 | AH7: 22 | AI7: 23 | AJ7: 24 | AK7: 25 | AL7: 26 | AM7: 27 | AN7: 28 | AO7: 29 | AP7: 30 | AQ7: 31 | AR7: 32 | AS7: 33 | AT7: 34 | AU7: 35 | AV7: 36 | AW7: 37 | AX7: 38 | AY7: 39 | AZ7: 40 | BA7: 41 | BB7: 42 | BC7: 43 | BD7: 44 | BE7: 45 | BF7: 46 | BG7: 47 | BH7: 48 | BI7: 49 | BJ7: 50 | BK7: 51 | BL7: 52 | BM7: 1-2022 | BN7: 2-2022 | BO7: 3-2022 | BP7: 4-2022 | BQ7: 5-2022 | BR7: 6-2022 | BS7: 7-2022 | BT7: 8-2022 | BU7: 9-2022 | BV7: 10-2022
C8: Filterlinje
A9: 22001 | B9: x | C9: Apilar | D9: Hallgruppen AS | E9: JFS | F9: 356 | G9: 1620 | H9: 1 | I9: 12 | J9: =SUM(M9:BL9) -> 356 | K9: =SUM(BM9:BV9) -> 0 | L9: =F9-J9-K9 -> 0 | M9: 15 | N9: 96 | O9: 100 | P9: 100 | W9: 45
A10: 22002 | C10: Killingmo | D10: Hallgruppen AS | E10: TA | F10: 338 | G10: 1553 | H10: =Prosjektplan!E11 -> 13 | I10: 16 | J10: =SUM(M10:BL10) -> 338 | K10: =SUM(BM10:BV10) -> 0 | L10: =F10-J10-K10 -> 0 | Y10: 15 | AA10: 75 | AB10: 75 | AC10: 75 | AD10: 75 | AE10: 23
A11: 22003 | C11: Aurevegen 2 | D11: Hallgruppen AS | E11: TA | F11: 582 | G11: 2400 | H11: =Prosjektplan!E9 -> 8 | I11: 16 | J11: =SUM(M11:BL11) -> 582 | K11: =SUM(BM11:BV11) -> 0 | L11: =F11-J11-K11 -> 0 | T11: =137.5-6.5-28 -> 103 | U11: =186-34-3 -> 149 | V11: =255-19-42-5 -> 189 | W11: =74-16-5 -> 53 | Y11: =89-15-2-6 -> 66 | AA11: 22
A12: 22006 | C12: Ihlen Lager | D12: Straye Stålbygg AS | E12: FE | F12: 1000 | G12: 5100 | H12: =Prosjektplan!E10 -> 12 | I12: 20 | J12: =SUM(M12:BL12) -> 1000 | K12: =SUM(BM12:BV12) -> 0 | L12: =F12-J12-K12 -> 0 | X12: =182-5-21-2.5 -> 153.5 | Y12: =46-6-6 -> 34 | Z12: =49.5-6 -> 43.5 | AA12: =47-2 -> 45 | AB12: 160 | AC12: 110 | AD12: 130 | AE12: 120 | AF12: 15 | AG12: 100 | AH12: 89
A13: 22010 | C13: Kolboten Tennishall Sofiemyr Tennishall | D13: Straye Stålbygg AS | E13: Jon | F13: 700 | G13: 2900 | H13: =Prosjektplan!E12 -> 42 | J13: =SUM(M13:BL13) -> 700 | K13: =SUM(BM13:BV13) -> 0 | L13: =F13-J13-K13 -> 0 | BA13: 150 | BB13: 75 | BC13: 150 | BD13: 150 | BE13: 150 | BF13: 25
A14: 22014 | C14: Ordfører Utnes vei 51 | D14: Entreprenør | E14: Tommy | F14: 297 | G14: 1187 | H14: 39 | J14: =SUM(M14:BL14) -> 297 | K14: =SUM(BM14:BV14) -> 0 | L14: =F14-J14-K14 -> 0 | AL14: 75 | BC14: 75 | BD14: 75 | BE14: 72
A15: 22015 | C15: Coop Ørebekk Obs bygg | D15: Straye Stålbygg AS | E15: Christian K | F15: 2155 | G15: 8224 | H15: 46 | J15: =SUM(M15:BL15) -> 300 | K15: =SUM(BM15:BV15) -> 1855 | L15: =F15-J15-K15 -> 0 | BJ15: 150 | BK15: 150 | BM15: 200 | BN15: 200 | BO15: 200 | BP15: 200 | BQ15: 200 | BR15: 200 | BS15: 200 | BT15: 200 | BU15: 200 | BV15: 55
A16: 22019 | C16: Skjeberg Marinesenter | D16: Straye Stålbygg AS | E16: Jon | F16: 369 | G16: 1715 | H16: =Prosjektplan!E15 -> 45 | J16: =SUM(M16:BL16) -> 369 | K16: =SUM(BM16:BV16) -> 0 | L16: =F16-J16-K16 -> 0 | BF16: 150 | BG16: 150 | BH16: 69
A17: 22021 | B17: x | C17: Asko Oslofjord | D17: Straye Stålbygg AS | E17: CFL | F17: 74 | G17: 125 | H17: 1 | I17: 2 | J17: =SUM(M17:BL17) -> 74 | K17: =SUM(BM17:BV17) -> 0 | L17: =F17-J17-K17 -> 0 | M17: 60 | N17: 14
A18: 22025 | C18: Dekkhotell Røyken | D18: Hallgruppen AS | E18: Christian F | F18: 813 | G18: 3808 | H18: 28 | J18: =SUM(M18:BL18) -> 813 | K18: =SUM(BM18:BV18) -> 0 | L18: =F18-J18-K18 -> 0 | AP18: 52 | AQ18: 40 | AR18: 180 | AS18: 200 | AT18: 200 | AU18: 141
A19: 23016 | C19: Stansefabrikken | D19: Holmskau | E19: Tommy | F19: 663 | G19: 3247 | H19: =Prosjektplan!E18 -> 40 | J19: =SUM(M19:BL19) -> 663 | K19: =SUM(BM19:BV19) -> 0 | L19: =F19-J19-K19 -> 0 | AZ19: 100 | BA19: 200 | BC19: 150 | BD19: 150 | BE19: 63
A20: 23019 | C20: Osloveien 624 | D20: Straye Stålbygg AS | E20: Jan | F20: 169 | G20: 581 | H20: 47 | J20: =SUM(M20:BL20) -> 0 | K20: =SUM(BM20:BV20) -> 169 | L20: =F20-J20-K20 -> 0 | BO20: 75 | BP20: 75 | BQ20: 19
A21: 23020 | C21: Møller Bil BT2 | D21: Straye Stålbygg AS | E21: Jon | F21: =392+258 -> 650 | G21: 3170 | H21: 28 | J21: =SUM(M21:BL21) -> 650 | K21: =SUM(BM21:BV21) -> 0 | L21: =F21-J21-K21 -> 0 | AN21: 100 | AO21: 100 | AP21: 100 | AQ21: 100 | AR21: 100 | AS21: 150
A22: 23023 | C22: Asko Oslofjord Miljøstasjon | D22: Straye Stålbygg AS | E22: Frode | F22: 0 | G22: 2226 | H22: 37 | I22: Var 880t | J22: =SUM(M22:BL22) -> 0 | K22: =SUM(BM22:BV22) -> 0 | L22: =F22-J22-K22 -> 0 | AW22: D100 | AX22: D100 | AY22: D100 | AZ22: D100 | BA22: D100 | BB22: D100 | BC22: D200
A23: 23036 | C23: Myrveien | D23: Entreprenør | E23: Tommy | F23: 268 | G23: 1136 | H23: =Prosjektplan!E22 -> 22 | J23: =SUM(M23:BL23) -> 0 | K23: =SUM(BM23:BV23) -> 268 | L23: =F23-J23-K23 -> 0 | BV23: 268
A24: 23038 | C24: Bulk Wood | D24: Thermica AS | E24: Christian F | F24: 639 | G24: 3027 | H24: 37 | J24: =SUM(M24:BL24) -> 639 | K24: =SUM(BM24:BV24) -> 0 | L24: =F24-J24-K24 -> 0 | AU24: 150 | AV24: 150 | AW24: 150 | AX24: 100 | AY24: 89
A25: 23040 | C25: Trondheimsveien 183- Vaskehall | D25: Straye Stålbygg AS | E25: Christian F | F25: 44 | G25: 98 | H25: 27 | I25: 21 | J25: =SUM(M25:BL25) -> 44 | K25: =SUM(BM25:BV25) -> 0 | L25: =F25-J25-K25 -> 0 | AM25: 44
A26: 23043 | C26: Rema1000 Ørebekk | D26: Straye Stålbygg AS | E26: Christian F | F26: 324 | G26: 1267 | H26: =Prosjektplan!E25 -> 50 | J26: =SUM(M26:BL26) -> 250 | K26: =SUM(BM26:BV26) -> 74 | L26: =F26-J26-K26 -> 0 | BJ26: 150 | BK26: 100 | BM26: 74
A27: 23049 | C27: Tilbygg Coop Manstad | D27: Straye Stålbygg AS | E27: Tommy | F27: 82 | G27: 217 | H27: =Prosjektplan!E26 -> 43 | J27: =SUM(M27:BL27) -> 82 | K27: =SUM(BM27:BV27) -> 0 | L27: =F27-J27-K27 -> 0 | BC27: 82
A28: 23050 | C28: Kvadratera | D28: Hallgruppen AS | E28: Tommy | F28: 460 | G28: 2080 | H28: 38 | J28: =SUM(M28:BL28) -> 460 | K28: =SUM(BM28:BV28) -> 0 | L28: =F28-J28-K28 -> 0 | AW28: 30 | AX28: 150 | AY28: 150 | AZ28: 130
A29: 23053 | C29: Reolteknikk | D29: Straye Stålbygg AS | E29: Christian F | F29: 570 | G29: 2518 | H29: =Prosjektplan!E28 -> 4 | J29: =SUM(M29:BL29) -> 0 | K29: =SUM(BM29:BV29) -> 570 | L29: =F29-J29-K29 -> 0 | BP29: 150 | BQ29: 150 | BR29: 150 | BS29: 120
A30: 23054 | C30: Asian Food | D30: Straye Stålbygg AS | E30: Christian F | F30: 1886 | G30: 8128 | H30: 17 | J30: =SUM(M30:BL30) -> 0 | K30: =SUM(BM30:BV30) -> 1886 | L30: =F30-J30-K30 -> 0 | BN30: 200 | BO30: 200 | BP30: 200 | BQ30: 200 | BR30: 200 | BS30: 200 | BT30: 200 | BU30: 200 | BV30: 286
A31: 23057 | C31: Lafinto | D31: Holmskau | E31: Tommy | F31: 396 | G31: 1822 | H31: 46 | J31: =SUM(M31:BL31) -> 396 | K31: =SUM(BM31:BV31) -> 0 | L31: =F31-J31-K31 -> 0 | BF31: 75 | BG31: 75 | BH31: 100 | BI31: 100 | BJ31: 46
A32: 23068 | C32: Thaugland- Bjørnerudveien 16 | D32: Straye Stålbygg AS | E32: Frode | F32: 348 | G32: 927 | H32: 49 | J32: =SUM(M32:BL32) -> 0 | K32: =SUM(BM32:BV32) -> 348 | L32: =F32-J32-K32 -> 0 | BO32: 100 | BP32: 100 | BQ32: 148
A33: 23097 | C33: Høstbakken 11 | D33: Straye Stålbygg AS | E33: Tommy | F33: 738 | G33: 2378 | H33: 3 | J33: =SUM(M33:BL33) -> 0 | K33: =SUM(BM33:BV33) -> 738 | L33: =F33-J33-K33 -> 0 | BO33: 150 | BP33: 150 | BQ33: 150 | BR33: 150 | BS33: 138
A34: 23101 | C34: Lagerseksjoner Moss+ Våler | D34: Straye Stålbygg AS | E34: Tommy | F34: 3480 | G34: 13250 | H34: 5 | J34: =SUM(M34:BL34) -> 0 | K34: =SUM(BM34:BV34) -> 3480 | L34: =F34-J34-K34 -> 0 | BM34: 200 | BN34: 200 | BO34: 200 | BP34: 200 | BQ34: 200 | BR34: 200 | BS34: 200 | BT34: 200 | BU34: 200 | BV34: 1680
A35: 23100 | C35: Atracco Arendal | D35: Straye Stålbygg AS | E35: ? | F35: 376 | G35: 1299 | H35: 6 | J35: =SUM(M35:BL35) -> 0 | K35: =SUM(BM35:BV35) -> 376 | L35: =F35-J35-K35 -> 0 | BP35: 150 | BQ35: 150 | BR35: 76
A36: 23055 | C36: Qmatec | D36: Straye Stålbygg AS | E36: Salmir | F36: 978 | G36: 4367 | H36: 5 | J36: =SUM(M36:BL36) -> 0 | K36: =SUM(BM36:BV36) -> 978 | L36: =F36-J36-K36 -> 0 | BP36: 100 | BQ36: 100 | BR36: 200 | BS36: 200 | BT36: 200 | BU36: 100 | BV36: 78
A37: 23005 | C37: Posten Moss | D37: Straye Stålbygg AS | E37: Salmir | F37: 4532 | G37: 20539 | J37: =SUM(M37:BL37) -> 0 | K37: =SUM(BM37:BV37) -> 4532 | L37: =F37-J37-K37 -> 0 | BR37: 1000 | BS37: 1000 | BT37: 1000 | BU37: 1000 | BV37: 532
A38: 23073 | C38: Vestre Vanemvei | D38: Straye Stålbygg AS | E38: Tommy | F38: 4291 | G38: 18883 | J38: =SUM(M38:BL38) -> 0 | K38: =SUM(BM38:BV38) -> 4291 | L38: =F38-J38-K38 -> 0 | BS38: 1000 | BT38: 1000 | BU38: 1000 | BV38: 1291
A39: 23042 | C39: Hallingplast | D39: Straye Stålbygg AS | E39: Tommy | F39: 1025 | G39: 4543 | H39: 50? | J39: =SUM(M39:BL39) -> 400 | K39: =SUM(BM39:BV39) -> 625 | L39: =F39-J39-K39 -> 0 | BJ39: 200 | BK39: 200 | BN39: 625
J40: =SUM(M40:BL40) -> 0 | K40: =SUM(BM40:BV40) -> 0 | L40: =F40-J40-K40 -> 0
...

Sheet Mont- Bemanning
A1: Bemanning | C1: =Prosjektliste_Prodplan!E2 -> 50
E2: =IF($C$1=E6,1,"") | F2: =IF($C$1=F6,1,"") | G2: =IF($C$1=G6,1,"") | H2: =IF($C$1=H6,1,"") | I2: =IF($C$1=I6,1,"") | J2: =IF($C$1=J6,1,"") | K2: =IF($C$1=K6,1,"") | L2: =IF($C$1=L6,1,"") | ... BL2: =IF($C$1=BL6,1,"")
A3: 0.05 | B3: Brutto kapasitet m/ korr sykefravær | C3: =(C4-(C4*$A$3)) -> 106.875 | D3: =(D4-(D4*$A$3)) -> 106.875 | E3: =(E4-(E4*$A$3)) -> 106.875 | F3: =(F4-(F4*$A$3)) -> 106.875 | G3: =(G4-(G4*$A$3)) -> 106.875 | H3: =(H4-(H4*$A$3)) -> 78.375 | I3: =(I4-(I4*$A$3)) -> 64.125 | J3: =(J4-(J4*$A$3)) -> 99.75 | ... BL3: =(BL4-(BL4*$A$3)) -> 0
A4: Totalt | B4: Netto kapasitet Timer | C4: =C5*$E$30 -> 112.5 | D4: =D5*$E$30 -> 112.5 | E4: =E5*$E$30 -> 112.5 | F4: =F5*$E$30 -> 112.5 | G4: =G5*$E$30 -> 112.5 | H4: =H5*$E$30 -> 82.5 | I4: =I5*$E$30 -> 67.5 | J4: =J5*$E$30 -> 105 | ... BL4: =BL5*$E$30 -> 0
A5: Totalt | B5: Netto kapasitet DAGSVERK | C5: =SUM(C8:C23)+C28 -> 3 | D5: =SUM(D8:D23)+D28 -> 3 | E5: =SUM(E8:E23)+E28 -> 3 | F5: =SUM(F8:F23)+F28 -> 3 | G5: =SUM(G8:G23)+G28 -> 3 | H5: =SUM(H8:H23)+H28 -> 2.2 | I5: =SUM(I8:I23)+I28 -> 1.8 | J5: =SUM(J8:J23)+J28 -> 2.8 | ... BL5: =SUM(BL8:BL23)+BL28 -> 0
A6: Ansatt nr | B6: Uke nr | C6: 1 | D6: 2 | E6: 3 | F6: 4 | G6: 5 | H6: 6 | I6: 7 | J6: 8 | K6: 9 | L6: 10 | M6: 11 | N6: 12 | O6: 13 | P6: 14 | Q6: 15 | R6: 16 | S6: 17 | T6: 18 | U6: 19 | V6: 20 | W6: 21 | X6: 22 | Y6: 23 | Z6: 24 | AA6: 25 | AB6: 26 | AC6: 27 | AD6: 28 | AE6: 29 | AF6: 30 | AG6: 31 | AH6: 32 | AI6: 33 | AJ6: 34 | AK6: 35 | AL6: 36 | AM6: 37 | AN6: 38 | AO6: 39 | AP6: 40 | AQ6: 41 | AR6: 42 | AS6: 43 | AT6: 44 | AU6: 45 | AV6: 46 | AW6: 47 | AX6: 48 | AY6: 49 | AZ6: 50 | BA6: 51 | BB6: 52 | BC6: 1-24 | BD6: 2-24 | BE6: 3-24 | BF6: 4-24 | BG6: 5-24 | BH6: 6-24 | BI6: 7-24 | BJ6: 8-24 | BK6: 9-24 | BL6: 10-24
B7: Navn\ Antall arbeidsdager | C7: 5 | D7: 5 | E7: 5 | F7: 5 | G7: 5 | H7: 5 | I7: 5 | J7: 5 | K7: 5 | L7: 5 | M7: 5 | N7: 5 | O7: 5 | P7: 3 | Q7: 4 | R7: 5 | S7: 5 | T7: 4 | U7: 4 | V7: 2 | W7: 5 | X7: 4 | Y7: 5 | Z7: 5 | AA7: 5 | AB7: 5 | AC7: 5 | AD7: 0 | AE7: 0 | AF7: 0 | AG7: 5 | AH7: 5 | AI7: 5 | AJ7: 5 | AK7: 5 | AL7: 5 | AM7: 5 | AN7: 5 | AO7: 5 | AP7: 5 | AQ7: 5 | AR7: 5 | AS7: 5 | AT7: 5 | AU7: 5 | AV7: 5 | AW7: 5 | AX7: 5 | AY7: 5 | AZ7: 5 | BA7: 5 | BB7: 0 | BC7: 5 | BD7: 5 | BE7: 5 | BF7: 5 | BG7: 5 | BH7: 5 | BI7: 5 | BJ7: 5 | BK7: 5 | BL7: 5
A8: 2 | B8: Mikal | C8: 1 | D8: 1 | E8: 1 | F8: 1 | G8: 1 | H8: 1 | I8: 0.2 | J8: 0.8 | K8: 1 | L8: 1 | M8: 1 | N8: 1 | O8: 1 | P8: 0.2 | Q8: 0.8 | R8: 1 | S8: 1 | T8: 1 | U8: 1 | V8: 1 | W8: 1 | X8: 1 | Y8: 1 | Z8: 1 | AA8: 1 | AB8: 1 | AC8: 1 | AD8: 1 | AE8: 1 | AF8: 1 | AG8: 1 | AH8: 1 | AI8: 1 | AJ8: 1 | AK8: 1 | AL8: 1 | AM8: 1 | AN8: 1 | AO8: 1 | AP8: 1 | AQ8: 1 | AR8: 1 | AS8: 1 | AT8: 1 | AU8: 1 | AV8: 1 | AW8: 1 | AX8: 1 | AY8: 1 | AZ8: 1 | BA8: 1 | BC8: 1 | BD8: 1 | BE8: 1 | BF8: 1 | BG8: 1 | BH8: 1 | BI8: 1 | BJ8: 1 | BK8: 1
A9: 3 | B9: Sebastian | C9: 1 | D9: 1 | E9: 1 | F9: 1 | G9: 1 | H9: 0.2 | I9: 1 | J9: 1 | K9: 1 | L9: 1 | M9: 1 | N9: 1 | O9: 1 | P9: 0.2 | Q9: 0.8 | R9: 1 | S9: 1 | T9: 1 | U9: 1 | V9: 1 | W9: 1 | X9: 1 | Y9: 1 | Z9: 1 | AA9: 1 | AB9: 1 | AC9: 1 | AD9: 1 | AE9: 1 | AF9: 1 | AG9: 1 | AH9: 1 | AI9: 1 | AJ9: 1 | AK9: 1 | AL9: 1 | AM9: 1 | AN9: 1 | AO9: 1 | AP9: 1 | AQ9: 1 | AR9: 1 | AS9: 1 | AT9: 1 | AU9: 1 | AV9: 1 | AW9: 1 | AX9: 1 | AY9: 1 | AZ9: 1 | BA9: 1 | BC9: 1 | BD9: 1 | BE9: 1 | BF9: 1 | BG9: 1 | BH9: 1 | BI9: 1 | BJ9: 1 | BK9: 1
A10: 4 | B10: Maciej Franczek | C10: 1 | D10: 1 | E10: 1 | F10: 1 | G10: 1 | H10: 1 | I10: 0.6 | J10: 1 | K10: 1 | L10: 1 | M10: 1 | N10: 1 | O10: 1 | P10: 0 | Q10: 0.8 | R10: 1 | S10: 1 | T10: 1 | U10: 1
A11: 5 | B11: Daniel Karolczak | K11: 0.6 | L11: 1 | M11: 1 | N11: 1 | O11: 1 | P11: 0.2 | Q11: 0.8 | R11: 1 | S11: 1 | T11: 1 | U11: 1 | V11: 1 | W11: 1 | X11: 1 | Y11: 1 | Z11: 1 | AA11: 1 | AB11: 1 | AC11: 1 | AD11: 1 | AE11: 1 | AF11: 1 | AG11: 1 | AH11: 1 | AI11: 1 | AJ11: 1 | AK11: 1 | AL11: 1 | AM11: 1 | AN11: 1 | AO11: 1 | AP11: 1 | AQ11: 1 | AR11: 1 | AS11: 1 | AT11: 1 | AU11: 1 | AV11: 1 | AW11: 1 | AX11: 1 | AY11: 1 | AZ11: 1 | BA11: 1 | BC11: 1 | BD11: 1 | BE11: 1 | BF11: 1 | BG11: 1 | BH11: 1 | BI11: 1 | BJ11: 1 | BK11: 1
A12: 6 | B12: Jakub Narloch | AD12: 1 | AE12: 1 | AF12: 1 | AG12: 1 | AH12: 1 | AI12: 1 | AJ12: 1 | AK12: 1 | AL12: 1 | AM12: 1 | AN12: 1 | AO12: 1 | AP12: 1 | AQ12: 1 | AR12: 1 | AS12: 1 | AT12: 1 | AU12: 1 | AV12: 1 | AW12: 1 | AX12: 1 | AY12: 1 | AZ12: 1 | BA12: 1 | BC12: 1 | BD12: 1 | BE12: 1 | BF12: 1 | BG12: 1 | BH12: 1 | BI12: 1 | BJ12: 1 | BK12: 1
A13: 7 | B13: Kacper Modrzejewski | AD13: 1 | AE13: 1 | AF13: 1 | AG13: 1 | AH13: 1 | AI13: 1 | AJ13: 1 | AK13: 1 | AL13: 1 | AM13: 1 | AN13: 1 | AO13: 1 | AP13: 1 | AQ13: 1 | AR13: 1 | AS13: 1 | AT13: 1 | AU13: 1 | AV13: 1 | AW13: 1 | AX13: 1 | AY13: 1 | AZ13: 1 | BA13: 1 | BC13: 1 | BD13: 1 | BE13: 1 | BF13: 1 | BG13: 1 | BH13: 1 | BI13: 1 | BJ13: 1 | BK13: 1
A14: 8 | B14: Mateusz | AH14: 1 | AI14: 1 | AJ14: 1 | AK14: 1 | AL14: 1 | AM14: 1 | AN14: 1 | AO14: 1 | AP14: 1 | AQ14: 1 | AR14: 1 | AS14: 1 | AT14: 1 | AU14: 1 | AV14: 1 | AW14: 1 | AX14: 1 | AY14: 1 | AZ14: 1 | BA14: 1 | BC14: 1 | BD14: 1 | BE14: 1 | BF14: 1 | BG14: 1 | BH14: 1 | BI14: 1 | BJ14: 1 | BK14: 1
A15: 9
A16: 10 | B16: Dawid | AJ16: 1 | AK16: 1 | AL16: 1 | AM16: 1 | AN16: 1 | AO16: 1 | AP16: 1 | AQ16: 1 | AR16: 1 | AS16: 1 | AT16: 1 | AU16: 1 | AV16: 1 | AW16: 1 | AX16: 1 | AY16: 1 | AZ16: 1 | BA16: 1 | BC16: 1 | BD16: 1 | BE16: 1 | BF16: 1 | BG16: 1 | BH16: 1 | BI16: 1 | BJ16: 1 | BK16: 1
A17: 11 | B17: Grzegorsz | AP17: 1 | AQ17: 1 | AR17: 1 | AS17: 1 | AT17: 1 | AU17: 1 | AV17: 1 | AW17: 1 | AX17: 1 | AY17: 1 | AZ17: 1 | BA17: 1 | BC17: 1 | BD17: 1 | BE17: 1 | BF17: 1 | BG17: 1 | BH17: 1 | BI17: 1 | BJ17: 1 | BK17: 1
A18: 12
A19: 13 | B19: Grzegorz | AP19: 1 | AQ19: 1 | AR19: 1 | AS19: 1 | AT19: 1 | AU19: 1 | AV19: 1 | AW19: 1 | AX19: 1 | AY19: 1 | AZ19: 1 | BA19: 1 | BC19: 1 | BD19: 1 | BE19: 1 | BF19: 1 | BG19: 1 | BH19: 1 | BI19: 1 | BJ19: 1 | BK19: 1
A20: 14 | B20: G1 | AP20: 1 | AQ20: 1 | AR20: 1 | AS20: 1 | AT20: 1 | AU20: 1 | AV20: 1 | AW20: 1 | AX20: 1 | AY20: 1 | AZ20: 1 | BA20: 1 | BC20: 1 | BD20: 1 | BE20: 1 | BF20: 1 | BG20: 1 | BH20: 1 | BI20: 1 | BJ20: 1 | BK20: 1
A21: 15 | B21: G2 | AP21: 1 | AQ21: 1 | AR21: 1 | AS21: 1 | AT21: 1 | AU21: 1 | AV21: 1 | AW21: 1 | AX21: 1 | AY21: 1 | AZ21: 1 | BA21: 1 | BC21: 1 | BD21: 1 | BE21: 1 | BF21: 1 | BG21: 1 | BH21: 1 | BI21: 1 | BJ21: 1 | BK21: 1
A22: 16 | B22: G3 | AP22: 1 | AQ22: 1 | AR22: 1 | AS22: 1 | AT22: 1 | AU22: 1 | AV22: 1 | AW22: 1 | AX22: 1 | AY22: 1 | AZ22: 1 | BA22: 1 | BC22: 1 | BD22: 1 | BE22: 1 | BF22: 1 | BG22: 1 | BH22: 1 | BI22: 1 | BJ22: 1 | BK22: 1
A23: 17 | B23: G4 | AP23: 1 | AQ23: 1 | AR23: 1 | AS23: 1 | AT23: 1 | AU23: 1 | AV23: 1 | AW23: 1 | AX23: 1 | AY23: 1 | AZ23: 1 | BA23: 1 | BC23: 1 | BD23: 1 | BE23: 1 | BF23: 1 | BG23: 1 | BH23: 1 | BI23: 1 | BJ23: 1 | BK23: 1
A24: A | B24: Innleie 1 | O24: 0.5 | P24: 0.2 | Q24: 1 | R24: 1 | S24: 1 | T24: 1 | U24: 1 | V24: 1
